Traceback with variables (most recent call last):
  File "/tmp/pytest-of-user/pytest-9/test_activate_by_import0/code.py", line 4, in <module>
    f(10)
      __name__ = '__main__'
      __doc__ = None
      __package__ = None
      __loader__ = <_frozen_importlib_external.SourceFileLoader object at 0x...>
      __spec__ = None
      __annotations__ = {}
      __builtins__ = <module 'builtins' (built-in)>
      __file__ = '/tmp/pytest-of-user/pytest-9/test_activate_by_import0/code.py'
      __cached__ = None
      traceback_with_variables = <module 'traceback_with_variables' from '/mnt/c/pro/rich_traceback/traceback_with_variables/__init__.py'>
      f = <function f at 0x7fe066b22dc0>
  File "/tmp/pytest-of-user/pytest-9/test_activate_by_import0/code.py", line 3, in f
    return n / 0
      n = 10
builtins.ZeroDivisionError: division by zero
